Workbook

Sheet comp valuation

Sheet DCF
A1: DCF Analysis: 3 stage DCF model include working capital projection, sensitivity analysis, and equity value implication
J3: revenue assumption: given the main business in the company and high correlation between copper price and stock price, the revenue growh could be in 3 satge , in the first stage, the growth rate is double digit and reinvesment rate keeps high, in the second stage the gap between demand and supply squeezes so revenue growth starts declining as well as capital expenditure and net working capital. In the final stage, the growth converge to the constant rate or perpetuity growth rate. In that case, we assume the fixed rate = 3% which is roughly equal to the GDP growth rate in China
A8: ticker | B8: 601168 SH
A9: date | B9: =DATE(2025,7,19) -> 45857
A10: current price | B10: 17
A11: implied price | B11: =S82 -> 14.623087
A13: Assumptions
A14: government bond rate | C14: =1.68% -> 0.0168
A15: default spread(coverage ratio) | C15: =0.6% -> 0.006
A16: pre-tax cost of debt | C16: =C14+C15 -> 0.0228
A17: equity market premium | C17: =5.28% -> 0.0528
A18: levered beta | C18: =C19*(1+J72/J75*(1-0.1)) -> 1.7213379
A19: unlevered beta | C19: =1.28 -> 1.28
A20: debt average maturity | C20: 8
A21: market debt value | C21: =J34*(1-(1+C16)^(-C20))/C16 + 'balance sheet '!G39/(1+DCF!C16)^(DCF!C20) -> 17060.597
F23: Historcial Period | L23: Projection Period -1 | T23: Projection Period - 2
F24: 2022 | G24: 2023 | H24: 2024 | I24: CAGR | J24: 2025-LTM | L24: 2026 E | M24: 2027 E | N24: 2028 E | O24: 2029 E | P24: 2030 E | Q24: CAGR | T24: 2031 E | U24: 2032 E | V24: 2033 E | W24: 2034 E | X24: 2035 E | Y24: 2036 E
D26: Operating data
D27: revenue | F27: =40238.43 -> 40238.43 | G27: =42748.12 -> 42748.12 | H27: =50025.6 -> 50025.6 | J27: ='income statement'!H11 -> 56670 | L27: =J27*(1+L28) -> 64603.8 | M27: =L27*(1+M28) -> 74294.37 | N27: =M27*(1+N28) -> 86181.469 | O27: =N27*(1+O28) -> 100832.32 | P27: =O27*(1+P28) -> 115957.17 | T27: =P27*(1+T28) -> 127552.88 | U27: =T27*(1+U28) -> 139032.64 | V27: =U27*(1+V28) -> 150155.25 | W27: =V27*(1+W28) -> 160666.12 | X27: =W27*(1+X28) -> 170306.09 | Y27: =X27*(1+Y28) -> 178821.39
D28: revenue yoy | F28: =5% -> 0.05 | G28: =G27/F27-1 -> 0.062370475 | H28: =H27/G27-1 -> 0.17024094 | J28: =J27/H27-1 -> 0.13282 | L28: =14% -> 0.14 | M28: =0.15 -> 0.15 | N28: =0.16 -> 0.16 | O28: 0.17 | P28: 0.15 | Q28: =(P27/J27)^(1/5)-1 -> 0.15395501 | T28: =0.1 -> 0.1 | U28: =T28-0.01 -> 0.09 | V28: =U28-0.01 -> 0.08 | W28: =V28-0.01 -> 0.07 | X28: =W28-0.01 -> 0.06 | Y28: =X28-0.01 -> 0.05
D32: net income | F32: 3417.35 | G32: 2789.28 | H32: =2931.55 -> 2931.55 | J32: =1870+H32-1620 -> 3181.55
D33: profit margin | F33: =F32/F27 -> 0.084927518 | G33: =G32/G27 -> 0.065249185 | H33: =H32/H27 -> 0.058600996 | I33: =AVERAGE(F33:H33) -> 0.069592567 | J33: =J32/J27 -> 0.056141698 | L33: =7% -> 0.07 | M33: 0.07 | N33: =7% -> 0.07 | O33: 0.07 | P33: =7% -> 0.07
D34: interest payment | F34: =736.5 -> 736.5 | G34: =702.65 -> 702.65 | H34: =625.15 -> 625.15 | J34: =282.34+625.15-340.37 -> 567.12
D35: income tax | F35: 578.04 | G35: 485.98 | H35: 698.69 | J35: =516.74+698.69-410.22 -> 805.21
D36: EBIT | F36: =F32+F34+F35 -> 4731.89 | G36: =G32+G34+G35 -> 3977.91 | H36: =H32+H34+H35 -> 4255.39 | J36: =J32+J35+J34 -> 4553.88 | L36: =L27*L37 -> 6460.38 | M36: =M27*M37 -> 7429.437 | N36: =N27*N37 -> 8618.1469 | O36: =O27*O37 -> 10083.232 | P36: =P27*P37 -> 11595.717 | T36: =T27*T37 -> 12755.288 | U36: =U27*U37 -> 13903.264 | V36: =V27*V37 -> 15015.525 | W36: =W27*W37 -> 16066.612 | X36: =X27*X37 -> 17030.609 | Y36: =Y27*Y37 -> 17882.139
D37: EBIT margin | F37: =F36/F27 -> 0.11759629 | G37: =G36/G27 -> 0.093054619 | H37: =H36/H27 -> 0.085064247 | I37: =AVERAGE(F37:H37) -> 0.098571718 | J37: =J36/J27 -> 0.080357861 | L37: =0.1 -> 0.1 | M37: 0.1 | N37: =0.1 -> 0.1 | O37: 0.1 | P37: =0.1 -> 0.1 | T37: =0.1 -> 0.1 | U37: 0.1 | V37: =0.1 -> 0.1 | W37: 0.1 | X37: =0.1 -> 0.1 | Y37: =0.1 -> 0.1
D40: EBITDA | F40: =F36+F49 -> 4925.87 | G40: =G36+G49 -> 4178.77 | H40: =H36+H49 -> 4440.11 | J40: =J36+J49 -> 4825.4388 | L40: =L36+L49 -> 6822.1613 | M40: =M36+M49 -> 7845.4855 | N40: =N36+N49 -> 9100.7631 | O40: =O36+O49 -> 10647.893 | P40: =P36+P49 -> 12245.077 | T40: =T36+T49 -> 13367.542 | U40: =U36+U49 -> 14459.395 | V40: =V36+V49 -> 15616.146 | W40: =W36+W49 -> 16709.277 | X40: =X36+X49 -> 17711.833 | Y40: =Y36+Y49 -> 18597.425
D42: net income before tax | F42: =5610.49 -> 5610.49 | G42: 4719.26 | H42: 5992.4 | J42: =3880+H42-3160 -> 6712.4
D44: effective income tax rate | F44: =F35/F42 -> 0.10302843 | G44: =G35/G42 -> 0.10297801 | H44: =H35/H42 -> 0.11659602 | J44: =J35/J42 -> 0.11995858 | L44: 0.12 | M44: 0.12 | N44: 0.12 | O44: 0.12 | P44: 0.12
D46: EBIAT | F46: =F36-F35 -> 4153.85 | G46: =G36-G35 -> 3491.93 | H46: =H36-H35 -> 3556.7 | J46: =J36-J35 -> 3748.67 | L46: =L27*L47 -> 5168.304 | M46: =M27*M47 -> 5943.5496 | N46: =N27*N47 -> 6894.5175 | O46: =O27*O47 -> 8066.5855 | P46: =P27*P47 -> 9276.5733 | T46: =T27*T47 -> 10204.231 | U46: =U27*U47 -> 11122.611 | V46: =V27*V47 -> 12012.42 | W46: =W27*W47 -> 12853.29 | X46: =X27*X47 -> 13624.487 | Y46: =Y27*Y47 -> 14305.712
D47: %sales | F47: =F46/F27 -> 0.10323092 | G47: =G46/G27 -> 0.081686165 | H47: =H46/H27 -> 0.071097598 | I47: =AVERAGE(F47:H47) -> 0.085338227 | J47: =J46/J27 -> 0.066149109 | L47: =0.08 -> 0.08 | M47: =0.08 -> 0.08 | N47: =0.08 -> 0.08 | O47: =0.08 -> 0.08 | P47: =0.08 -> 0.08 | T47: =0.08 -> 0.08 | U47: =0.08 -> 0.08 | V47: =0.08 -> 0.08 | W47: =0.08 -> 0.08 | X47: =0.08 -> 0.08 | Y47: =0.08 -> 0.08
D49: D&A | F49: ='income statement'!D26 -> 193.98 | G49: ='income statement'!E26 -> 200.86 | H49: ='income statement'!F26 -> 184.72 | J49: =J52*I50 -> 271.55879 | L49: =L52*L50 -> 361.78128 | M49: =M52*M50 -> 416.04847 | N49: =N52*N50 -> 482.61623 | O49: =O52*O50 -> 564.66099 | P49: =P52*P50 -> 649.36013 | T49: =T52*T50 -> 612.25384 | U49: =U52*U50 -> 556.13057 | V49: =V52*V50 -> 600.62102 | W49: =W52*W50 -> 642.66449 | X49: =X52*X50 -> 681.22436 | Y49: =Y52*Y50 -> 715.28558
D50: % Capex | F50: =F49/F52 -> 0.1024701 | G50: =G49/G52 -> 0.069537822 | H50: =H49/H52 -> 0.056128836 | I50: =AVERAGE(F50:H50) -> 0.076045587 | J50: 0.08 | L50: =0.08 -> 0.08 | M50: =0.08 -> 0.08 | N50: =0.08 -> 0.08 | O50: =0.08 -> 0.08 | P50: =0.08 -> 0.08 | T50: =0.08 -> 0.08 | U50: =0.08 -> 0.08 | V50: =0.08 -> 0.08 | W50: =0.08 -> 0.08 | X50: =0.08 -> 0.08 | Y50: =0.08 -> 0.08
D52: capitl expenditures | F52: =1893.04 -> 1893.04 | G52: =2888.5 -> 2888.5 | H52: =3291 -> 3291 | J52: =1480+H52-1200 -> 3571 | L52: =L53*L27 -> 4522.266 | M52: =M53*M27 -> 5200.6059 | N52: =N53*N27 -> 6032.7028 | O52: =O53*O27 -> 7058.2623 | P52: =P53*P27 -> 8117.0017 | T52: =T27*T53 -> 7653.173 | U52: =U27*U53 -> 6951.6322 | V52: =V27*V53 -> 7507.7627 | W52: =W27*W53 -> 8033.3061 | X52: =X27*X53 -> 8515.3045 | Y52: =Y27*Y53 -> 8941.0697
D53: %sales | F53: =F52/F27 -> 0.047045573 | G53: =G52/G27 -> 0.067570223 | H53: =H52/H27 -> 0.065786317 | I53: =AVERAGE(F53:H53) -> 0.060134038 | J53: =J52/J27 -> 0.06301394 | L53: =0.07 -> 0.07 | M53: 0.07 | N53: =0.07 -> 0.07 | O53: 0.07 | P53: =0.07 -> 0.07 | T53: =0.06 -> 0.06 | U53: =0.05 -> 0.05 | V53: =0.05 -> 0.05 | W53: =0.05 -> 0.05 | X53: =0.05 -> 0.05 | Y53: =0.05 -> 0.05
D55: reinvestment rate | L55: =(L52-L49+(-1)*L58)/L46 -> 0.91953805 | M55: =(M52-M49+(-1)*M58)/M46 -> 0.92833234 | N55: =(N52-N49+(-1)*N58)/N46 -> 0.93542041 | O55: =(O52-O49+(-1)*O58)/O46 -> 0.94238731 | P55: =(P52-P49+(-1)*P58)/P46 -> 0.92833234
D56: return of IC | L56: =L46/(L52-L49+'working capital projection'!J24) -> 0.57124971 | M56: =M46/(M52-M49+'working capital projection'!K24) -> 0.57124971 | N56: =N46/(N52-N49+'working capital projection'!L24) -> 0.57124971 | O56: =O46/(O52-O49+'working capital projection'!M24) -> 0.57124971 | P56: =P46/(P52-P49+'working capital projection'!N24) -> 0.57124971
D58: change in net working capital | F58: =-1*'working capital projection'!D26 -> -1800 | G58: =-1*'working capital projection'!E26 -> 2889.72 | H58: =-1*'working capital projection'!F26 -> -847.78 | J58: =-1*'working capital projection'!H26 -> -1198.0818 | L58: =-1*'working capital projection'!J26 -> -591.96747 | M58: =-1*'working capital projection'!K26 -> -733.03188 | N58: =-1*'working capital projection'!L26 -> -899.18578 | O58: =-1*'working capital projection'!M26 -> -1108.2465 | P58: =-1*'working capital projection'!N26 -> -1144.1015 | T58: =-1*'working capital projection'!P26 -> -877.14449 | U58: =-1*'working capital projection'!Q26 -> -868.37304 | V58: =-1*'working capital projection'!R26 -> -841.35699 | W58: =-1*'working capital projection'!S26 -> -795.08236 | X58: =-1*'working capital projection'!T26 -> -729.2041 | Y58: =-1*'working capital projection'!U26 -> -644.13029
D60: free cash flow | F60: =F46+F49-F52+F58 -> 654.79 | G60: =G46+G49-G52+G58 -> 3694.01 | H60: =H46+H49-H52+H58 -> -397.36 | J60: =J46+J49-J52+J58 -> -748.85297 | L60: =L46+L49-L52+L58 -> 415.85181 | M60: =M46+M49-M52+M58 -> 425.96029 | N60: =N46+N49-N52+N58 -> 445.24514 | O60: =O46+O49-O52+O58 -> 464.7377 | P60: =P46+P49-P52+P58 -> 664.8303 | T60: =T46+T49-T52+T58 -> 2286.167 | U60: =U46+U49-U52+U58 -> 3858.7368 | V60: =V46+V49-V52+V58 -> 4263.9217 | W60: =W46+W49-W52+W58 -> 4667.5658 | X60: =X46+X49-X52+X58 -> 5061.2029 | Y60: =Y46+Y49-Y52+Y58 -> 5435.7971
D61: discount factor | J61: =1/(1+J85) -> 0.92445272 | L61: =1/(1+$J$85)^2 -> 0.85461283 | M61: =1/(1+$J$85)^3 -> 0.79004915 | N61: =1/(1+$J$85)^4 -> 0.73036309 | O61: =1/(1+$J$85)^5 -> 0.67518614 | P61: =1/(1+$J$85)^6 -> 0.62417767 | T61: =1/(1+$J$85)^7 -> 0.57702274 | U61: =1/(1+$J$85)^8 -> 0.53343024 | V61: =1/(1+$J$85)^9 -> 0.49313104 | W61: =1/(1+$J$85)^10 -> 0.45587633 | X61: =1/(1+$J$85)^11 -> 0.42143611 | Y61: =1/(1+$J$85)^12 -> 0.38959776
...

Sheet working capital projection
A1: working capital projection : current asset means non cash asset and current libailties means non interesr bearing liabilties
D5: historical period | J5: projection period
D7: 2022A | E7: 2023A | F7: 2024A | G7: 3 year avg | H7: 2025-LTM | J7: 2026 E | K7: 2027 E | L7: 2028 E | M7: 2029 E | N7: 2030 E | P7: 2031 E | Q7: 2032 E | R7: 2033 E | S7: 2034 E | T7: 2035 E | U7: 2036 E
B8: sales | D8: ='income statement'!D11 -> 40238.43 | E8: ='income statement'!E11 -> 42748.12 | F8: ='income statement'!F11 -> 50025.6 | H8: =DCF!J27 -> 56670 | J8: =DCF!L27 -> 64603.8 | K8: =DCF!M27 -> 74294.37 | L8: =DCF!N27 -> 86181.469 | M8: =DCF!O27 -> 100832.32 | N8: =DCF!P27 -> 115957.17 | P8: =DCF!T27 -> 127552.88 | Q8: =DCF!U27 -> 139032.64 | R8: =DCF!V27 -> 150155.25 | S8: =DCF!W27 -> 160666.12 | T8: =DCF!X27 -> 170306.09 | U8: =DCF!Y27 -> 178821.39
B9: cogs | D9: ='income statement'!D14 -> 33045.05 | E9: ='income statement'!E14 -> 35606.02 | F9: ='income statement'!F14 -> 40877.25 | H9: ='income statement'!H14 -> 46682.549 | J9: =J8*J10 -> 52975.116 | K9: =K8*K10 -> 60921.383 | L9: =L8*L10 -> 70668.805 | M9: =M8*M10 -> 82682.502 | N9: =N8*N10 -> 95084.877
B10: % sales | D10: =D9/D8 -> 0.8212311 | E10: =E9/E8 -> 0.83292599 | F10: =F9/F8 -> 0.81712663 | H10: =H9/H8 -> 0.82376124 | J10: =0.82 -> 0.82 | K10: =0.82 -> 0.82 | L10: =0.82 -> 0.82 | M10: =0.82 -> 0.82 | N10: =0.82 -> 0.82
B12: current asset
B13: accounts receivable | D13: ='balance sheet '!D11 -> 5222.21 | E13: ='balance sheet '!E11 -> 2695.81 | F13: ='balance sheet '!F11 -> 3535.25 | H13: =H8/365*J31 -> 4657.8082 | J13: =J8/365*J31 -> 5309.9014 | K13: =K8/365*K31 -> 6106.3866 | L13: =L8/365*L31 -> 7083.4084 | M13: =M8/365*M31 -> 8287.5879 | N13: =N8/365*N31 -> 9530.726
B14: inventories | D14: ='balance sheet '!D12 -> 3523.7 | E14: ='balance sheet '!E12 -> 3162.14 | F14: ='balance sheet '!F12 -> 5112.9 | H14: =H9/365*J32 -> 4987.9984 | J14: =J9/365*J32 -> 5660.3549 | K14: =K9/365*K32 -> 6509.4081 | L14: =L9/365*L32 -> 7550.9134 | M14: =M9/365*M32 -> 8834.5687 | N14: =N9/365*N32 -> 10159.754
B15: prepaid expenses and other | D15: ='balance sheet '!D13+'balance sheet '!D14 -> 1648.24 | E15: ='balance sheet '!E13+'balance sheet '!E14 -> 896.36 | F15: ='balance sheet '!F13+'balance sheet '!F14 -> 1010.15 | H15: =H8*J33 -> 1530.09 | J15: =J8*J33 -> 1744.3026 | K15: =K8*K33 -> 2005.948 | L15: =L8*L33 -> 2326.8997 | M15: =M8*M33 -> 2722.4726 | N15: =N8*N33 -> 3130.8435
B16: total current assets | D16: =SUM(D13:D15) -> 10394.15 | E16: =SUM(E13:E15) -> 6754.31 | F16: =SUM(F13:F15) -> 9658.3 | H16: =SUM(H13:H15) -> 11175.897 | J16: =SUM(J13:J15) -> 12714.559 | K16: =SUM(K13:K15) -> 14621.743 | L16: =SUM(L13:L15) -> 16961.221 | M16: =SUM(M13:M15) -> 19844.629 | N16: =SUM(N13:N15) -> 22821.324
B18: current liablities
B19: accounts payable | D19: ='balance sheet '!D31 -> 2525.01 | E19: ='balance sheet '!E31 -> 2248.95 | F19: ='balance sheet '!F31 -> 2801.68 | H19: =H9/365*J35 -> 3197.4349 | J19: =J9/365*J35 -> 3628.4326 | K19: =K9/365*K35 -> 4172.6975 | L19: =L9/365*L35 -> 4840.3291 | M19: =M9/365*M35 -> 5663.185 | N19: =N9/365*N35 -> 6512.6628
B20: accrued liabilties | D20: ='balance sheet '!D32 -> 366.01 | E20: ='balance sheet '!E32 -> 358.89 | F20: ='balance sheet '!F32 -> 467.13
B21: other liabilities | D21: ='balance sheet '!D35 -> 2364.36 | E21: ='balance sheet '!E35 -> 1897.42 | F21: ='balance sheet '!F35 -> 3292.66 | H21: =H8*J36 -> 3683.55 | J21: =J8*J36 -> 4199.247 | K21: =K8*K36 -> 4829.1341 | L21: =L8*L36 -> 5601.7955 | M21: =M8*M36 -> 6554.1007 | N21: =N8*N36 -> 7537.2158
B22: total current liabilities | D22: =SUM(D19:D21) -> 5255.38 | E22: =SUM(E19:E21) -> 4505.26 | F22: =SUM(F19:F21) -> 6561.47 | H22: =SUM(H19+H21) -> 6880.9849 | J22: =J19+J21 -> 7827.6796 | K22: =K19+K21 -> 9001.8315 | L22: =L19+L21 -> 10442.125 | M22: =M19+M21 -> 12217.286 | N22: =N19+N21 -> 14049.879
B24: net working capital | D24: =D16-D22 -> 5138.77 | E24: =E16-E22 -> 2249.05 | F24: =F16-F22 -> 3096.83 | H24: =H16-H22 -> 4294.9118 | J24: =J16-J22 -> 4886.8792 | K24: =K16-K22 -> 5619.9111 | L24: =L16-L22 -> 6519.0969 | M24: =M16-M22 -> 7627.3434 | N24: =N16-N22 -> 8771.4449 | P24: =P8*P25 -> 9648.5894 | Q24: =Q8*Q25 -> 10516.962 | R24: =R8*R25 -> 11358.319 | S24: =S8*S25 -> 12153.402 | T24: =T8*T25 -> 12882.606 | U24: =U8*U25 -> 13526.736
B25: %sales | D25: =D24/D8 -> 0.12770801 | E25: =E24/E8 -> 0.05261167 | F25: =F24/F8 -> 0.061904905 | H25: =H24/H8 -> 0.075788102 | J25: =J24/J8 -> 0.075643836 | K25: =K24/K8 -> 0.075643836 | L25: =L24/L8 -> 0.075643836 | M25: =M24/M8 -> 0.075643836 | N25: =N24/N8 -> 0.075643836 | P25: 0.075643836 | Q25: 0.075643836 | R25: 0.075643836 | S25: 0.075643836 | T25: 0.075643836 | U25: 0.075643836
B26: (increase)/ decrease in capital | D26: 1800 | E26: =E24-D24 -> -2889.72 | F26: =F24-E24 -> 847.78 | H26: =H24-F24 -> 1198.0818 | J26: =J24-H24 -> 591.96747 | K26: =K24-J24 -> 733.03188 | L26: =L24-K24 -> 899.18578 | M26: =M24-L24 -> 1108.2465 | N26: =N24-M24 -> 1144.1015 | P26: =P24-N24 -> 877.14449 | Q26: =Q24-P24 -> 868.37304 | R26: =R24-Q24 -> 841.35699 | S26: =S24-R24 -> 795.08236 | T26: =T24-S24 -> 729.2041 | U26: =U24-T24 -> 644.13029
B30: Assumptions
B31: days sales outstanding | D31: =D13/D8*365 -> 47.370304 | E31: =E13/E8*365 -> 23.01787 | F31: =F13/F8*365 -> 25.794118 | G31: =AVERAGE(D31:F31) -> 32.060764 | J31: 30 | K31: 30 | L31: 30 | M31: 30 | N31: 30
B32: day inventory held | D32: =D14/D9*365 -> 38.921124 | E32: =E14/E9*365 -> 32.415336 | F32: =F14/F9*365 -> 45.653964 | G32: =AVERAGE(D32:F32) -> 38.996808 | J32: 39 | K32: 39 | L32: 39 | M32: 39 | N32: 39
B33: prepaid % sales | D33: =D15/D8 -> 0.040961837 | E33: =E15/E8 -> 0.020968407 | F33: =F15/F8 -> 0.020192661 | G33: =AVERAGE(D33:F33) -> 0.027374302 | J33: 0.027 | K33: 0.027 | L33: 0.027 | M33: 0.027 | N33: 0.027
B35: days payable outstanding | D35: =D19/D9*365 -> 27.890067 | E35: =E19/E9*365 -> 23.054156 | F35: =F19/F9*365 -> 25.016683 | G35: =AVERAGE(D35:F35) -> 25.320302 | J35: 25 | K35: 25 | L35: 25 | M35: 25 | N35: 25
B36: accrued % sales | D36: =(D20+D21)/D8 -> 0.067854785 | E36: =(E20+E21)/E8 -> 0.052781502 | F36: =(F20+F21)/F8 -> 0.075157319 | G36: =AVERAGE(D36:F36) -> 0.065264535 | J36: =6.5% -> 0.065 | K36: =6.5% -> 0.065 | L36: =6.5% -> 0.065 | M36: =6.5% -> 0.065 | N36: =6.5% -> 0.065

Sheet income statement
A1: income statement
A3: ticker | B3: 601168 SH
A4: date | B4: 07/19/2025
A5: unit | B5: million
C6: reported income statement
D9: Fiscal Year Ending Decemeber 31
D10: 2022A | E10: 2023A | F10: 2024A | G10: CAGR | H10: 2025 LTM | I10: 2026 E | J10: 2027 E
C11: revenue | D11: 40238.43 | E11: 42748.12 | F11: 50025.6 | H11: =(31.62+50.03-24.98)*1000 -> 56670
C12: yoy growth | D12: na | E12: =E11/D11-1 -> 0.062370475 | F12: =F11/E11-1 -> 0.17024094 | G12: =(F11/D11)^(1/2)-1 -> 0.11500198 | H12: =H11/F11-1 -> 0.13282
C14: cost of goods sold | D14: 33045.05 | E14: 35606.02 | F14: 40877.25 | H14: =H11*G15 -> 46682.549
C15: %sales | D15: =D14/D11 -> 0.8212311 | E15: =E14/E11 -> 0.83292599 | F15: =F14/F11 -> 0.81712663 | G15: =AVERAGE(D15:F15) -> 0.82376124
C16: gross profit | D16: =D11-D14 -> 7193.38 | E16: =E11-E14 -> 7142.1 | F16: =F11-F14 -> 9148.35
C17: %margin | D17: =D16/D11 -> 0.1787689 | E17: =E16/E11 -> 0.16707401 | F17: =F16/F11 -> 0.18287337 | G17: =AVERAGE(D17:F17) -> 0.17623876
C22: SGA | D22: 871.06 | E22: 988.57 | F22: 1194.52
C23: % of sales | D23: =D22/D11 -> 0.021647465 | E23: =E22/E11 -> 0.023125461 | F23: =F22/F11 -> 0.023878174
C24: R&D | D24: =358.69 -> 358.69 | E24: 526.12 | F24: 577.76
C25: % of sales | D25: =D24/D11 -> 0.0089141152 | E25: =E24/E11 -> 0.012307442 | F25: =F24/F11 -> 0.011549287
C26: depreciation & amortization | D26: 193.98 | E26: 200.86 | F26: 184.72
C27: % of sales | D27: =D26/D11 -> 0.0048207646 | E27: =E26/E11 -> 0.0046986862 | F27: =F26/F11 -> 0.0036925094
C28: other operating expenses | D28: =-60.97+190.9 -> 129.93 | E28: =66.69+429.11 -> 495.8 | F28: =562.94+86.79 -> 649.73
C29: total operating expenses | D29: =D22+D24+D26+D28+D14 -> 34598.71 | E29: =E22+E24+E26+E28+E14 -> 37817.37 | F29: =F22+F24+F26+F28+F14 -> 43483.98
C31: Operating income | D31: =D11-D29 -> 5639.72 | E31: =E11-E29 -> 4930.75 | F31: =F11-F29 -> 6541.62
C32: other , net | D32: 4.02 | E32: 8.79 | F32: -129.68
C34: net income before taxes | D34: =D31+D32 -> 5643.74 | E34: =E31+E32 -> 4939.54 | F34: =F31+F32 -> 6411.94
C35: provision for income taxes | D35: 578.04 | E35: =485.98 -> 485.98 | F35: =698.69 -> 698.69
C36: noncontrolling interest | D36: =1615.1 -> 1615.1 | E36: =1444 -> 1444 | F36: =2362.16 -> 2362.16
C38: net income | D38: =D34-D35-D36 -> 3450.6 | E38: =E34-E35-E36 -> 3009.56 | F38: =F34-F35-F36 -> 3351.09
C39: common shares | D39: =2383 -> 2383 | E39: 2383 | F39: =2383 -> 2383
C40: earning per share | D40: =D38/D39 -> 1.4480067 | E40: =E38/E39 -> 1.2629291 | F40: =F38/F39 -> 1.4062484
C43: EBIT
C44: EBIT MARGIN
C48: Adjusted income statement

Sheet balance sheet 
A1: balance sheet
A3: ticker | B3: 601168 SH
A4: date | B4: 07/19/2025
A5: unit | B5: 1 = 10k
F6: actual
D7: 2022A | E7: 2023A | F7: 2024A | G7: 2025- LTM
B8: asset
B10: cash and marketable securities | D10: 5142.05 | E10: 4655.2 | F10: 3648.83 | G10: =3290+3310-5130 -> 1470 | H10: =SUM(G10:G11) -> 1470
B11: total receivable | D11: 5222.21 | E11: 2695.81 | F11: 3535.25
B12: inventories | D12: 3523.7 | E12: 3162.14 | F12: 5112.9
B13: prepaid expense | D13: 261.52 | E13: 102.61 | F13: 202.5
B14: other current asset | D14: 1386.72 | E14: 793.75 | F14: 807.65
B15: total current asset | D15: =SUM(D10:D14) -> 15536.2 | E15: =SUM(E10:E14) -> 11409.51 | F15: =SUM(F10:F14) -> 13307.13
B17: PPE | D17: 34584.25 | E17: 36290.22 | F17: 39823 | I17: =F17-E17 -> 3532.78
B18: PPE accu depreciation | D18: -9013.35 | E18: =-10305.82 -> -10305.82 | F18: =-11775.27 -> -11775.27 | I18: =E17-D17 -> 1705.97
B19: net ppe | D19: =D17+D18 -> 25570.9 | E19: =E17+E18 -> 25984.4 | F19: =F17+F18 -> 28047.73
B20: intangible assets | D20: 6254.76 | E20: =6421.24 -> 6421.24 | F20: =6141.12 -> 6141.12
B21: goodwill | D21: 15.71 | E21: 15.71 | F21: 15.71
B22: long term investment | D22: 5043.65 | E22: 5549 | F22: 5420.84
B23: other long term assets | D23: 689.65 | E23: 629.26 | F23: 620.83
B24: total non current asset | D24: =SUM(D19:D23) -> 37574.67 | E24: =SUM(E19:E23) -> 38599.61 | F24: =SUM(F19:F23) -> 40246.23
B25: total asset | D25: =D15+D24 -> 53110.87 | E25: =E15+E24 -> 50009.12 | F25: =F15+F24 -> 53553.36
B29: Liabilities
B31: accounts payable | D31: 2525.01 | E31: 2248.95 | F31: 2801.68
B32: accrued expenses | D32: 366.01 | E32: 358.89 | F32: 467.13
B33: notes payable/short term debt | D33: 11062.61 | E33: 8110.19 | F33: =5203.61 -> 5203.61
B34: current port of LT debt/ capital lease | D34: 3683.86 | E34: 2733.48 | F34: 2504.04
B35: other current liabilities | D35: 2364.36 | E35: 1897.42 | F35: =3292.66 -> 3292.66
B36: total current liability | D36: =SUM(D31:D35) -> 20001.85 | E36: =SUM(E31:E35) -> 15348.93 | F36: =SUM(F31:F35) -> 14269.12
B39: long term debt | D39: 9950.64 | E39: 13595.16 | F39: 15716.43 | G39: =14940+F39-15140 -> 15516.43
B40: capital lease obiligations | D40: 1108.47 | E40: 1008.96 | F40: 258.5
B41: total long term debt | D41: =D39+D40 -> 11059.11 | E41: =E39+E40 -> 14604.12 | F41: =F39+F40 -> 15974.93
B42: total debt
B43: deferred income tax | D43: 250.76 | E43: 237.94 | F43: 223.73
B44: other liabilities | D44: 1572.26 | E44: 1532.19 | F44: 1709.88
B46: total liab | D46: =D36+D41+D43+D44 -> 32883.98 | E46: =E36+E41+E43+E44 -> 31723.18 | F46: =F36+F41+F43+F44 -> 32177.66
B49: shareholders equity
B50: common stock | D50: 2383 | E50: 2383 | F50: 2383
B51: APIC | D51: 5373.16 | E51: 4980.71 | F51: 4994.78
B52: retained earning | D52: 8369.74 | E52: 7803.32 | F52: 9560.32
...

Sheet cash flow
A1: cash flow
A3: ticker | B3: 601168 SH
A4: date | B4: 07/19/2025
A5: unit | B5: 1 = 10k
F6: actual
E7: 2022 | F7: 2023 | G7: 2024 | H7: 2025 -LTM
B9: cash taxes paid
B10: changes in workigin capital
B11: cash from operating activities
B13: capital expenditures | E13: =1893.04 -> 1893.04 | F13: 2888.53 | G13: 3290.88
B14: other investing cash flow
B15: cash from investing activities
B17: financing cash flow items
B18: total cash dividend paid
B19: issuance of debt
B20: cash from financing activities
B22: investing cash flow
B23: cash received from disposal investment
B24: cash received from return of investment
B25: other inflow
B26: total cash inflow from investing
B28: cash paid to acquire ppe
... B51: end period cash
